Workbook

Sheet Summary by Asset
A1: Momentum & Allocation Summary by Asset (108 monthly rebalances, 2016-2024)
A3: Ticker | B3: Gate Pass Rate | C3: Selection Rate | D3: Avg Weight (Overall) | E3: Avg Weight (When Selected) | F3: Avg AbsMomBlend (When Gate Passed) | G3: Avg RelMom6M (When Gate Passed) | H3: Avg Vol20D (When Gate Passed)
A4: SPY | B4: =COUNTIFS('Raw Data'!$B$2:$B$649,A4,'Raw Data'!$F$2:$F$649,1)/COUNTIFS('Raw Data'!$B$2:$B$649,A4) -> 0.84259259 | C4: =COUNTIFS('Raw Data'!$B$2:$B$649,A4,'Raw Data'!$H$2:$H$649,1)/COUNTIFS('Raw Data'!$B$2:$B$649,A4) -> 0.47222222 | D4: =AVERAGEIFS('Raw Data'!$G$2:$G$649,'Raw Data'!$B$2:$B$649,A4) -> 0.27133497 | E4: =IFERROR(AVERAGEIFS('Raw Data'!$G$2:$G$649,'Raw Data'!$B$2:$B$649,A4,'Raw Data'!$H$2:$H$649,1),0) -> 0.57459171 | F4: =IFERROR(AVERAGEIFS('Raw Data'!$C$2:$C$649,'Raw Data'!$B$2:$B$649,A4,'Raw Data'!$F$2:$F$649,1),0) -> 0.11138369 | G4: =IFERROR(AVERAGEIFS('Raw Data'!$D$2:$D$649,'Raw Data'!$B$2:$B$649,A4,'Raw Data'!$F$2:$F$649,1),0) -> 0.099736088 | H4: =IFERROR(AVERAGEIFS('Raw Data'!$E$2:$E$649,'Raw Data'!$B$2:$B$649,A4,'Raw Data'!$F$2:$F$649,1),0) -> 0.0077309451
A5: QQQ | B5: =COUNTIFS('Raw Data'!$B$2:$B$649,A5,'Raw Data'!$F$2:$F$649,1)/COUNTIFS('Raw Data'!$B$2:$B$649,A5) -> 0.81481481 | C5: =COUNTIFS('Raw Data'!$B$2:$B$649,A5,'Raw Data'!$H$2:$H$649,1)/COUNTIFS('Raw Data'!$B$2:$B$649,A5) -> 0.62962963 | D5: =AVERAGEIFS('Raw Data'!$G$2:$G$649,'Raw Data'!$B$2:$B$649,A5) -> 0.28910834 | E5: =IFERROR(AVERAGEIFS('Raw Data'!$G$2:$G$649,'Raw Data'!$B$2:$B$649,A5,'Raw Data'!$H$2:$H$649,1),0) -> 0.45917207 | F5: =IFERROR(AVERAGEIFS('Raw Data'!$C$2:$C$649,'Raw Data'!$B$2:$B$649,A5,'Raw Data'!$F$2:$F$649,1),0) -> 0.16296226 | G5: =IFERROR(AVERAGEIFS('Raw Data'!$D$2:$D$649,'Raw Data'!$B$2:$B$649,A5,'Raw Data'!$F$2:$F$649,1),0) -> 0.14457059 | H5: =IFERROR(AVERAGEIFS('Raw Data'!$E$2:$E$649,'Raw Data'!$B$2:$B$649,A5,'Raw Data'!$F$2:$F$649,1),0) -> 0.010424648
A6: GLD | B6: =COUNTIFS('Raw Data'!$B$2:$B$649,A6,'Raw Data'!$F$2:$F$649,1)/COUNTIFS('Raw Data'!$B$2:$B$649,A6) -> 0.73148148 | C6: =COUNTIFS('Raw Data'!$B$2:$B$649,A6,'Raw Data'!$H$2:$H$649,1)/COUNTIFS('Raw Data'!$B$2:$B$649,A6) -> 0.31481481 | D6: =AVERAGEIFS('Raw Data'!$G$2:$G$649,'Raw Data'!$B$2:$B$649,A6) -> 0.17474631 | E6: =IFERROR(AVERAGEIFS('Raw Data'!$G$2:$G$649,'Raw Data'!$B$2:$B$649,A6,'Raw Data'!$H$2:$H$649,1),0) -> 0.55507653 | F6: =IFERROR(AVERAGEIFS('Raw Data'!$C$2:$C$649,'Raw Data'!$B$2:$B$649,A6,'Raw Data'!$F$2:$F$649,1),0) -> 0.087522924 | G6: =IFERROR(AVERAGEIFS('Raw Data'!$D$2:$D$649,'Raw Data'!$B$2:$B$649,A6,'Raw Data'!$F$2:$F$649,1),0) -> 0.084541051 | H6: =IFERROR(AVERAGEIFS('Raw Data'!$E$2:$E$649,'Raw Data'!$B$2:$B$649,A6,'Raw Data'!$F$2:$F$649,1),0) -> 0.0085282532
A7: EEM | B7: =COUNTIFS('Raw Data'!$B$2:$B$649,A7,'Raw Data'!$F$2:$F$649,1)/COUNTIFS('Raw Data'!$B$2:$B$649,A7) -> 0.62037037 | C7: =COUNTIFS('Raw Data'!$B$2:$B$649,A7,'Raw Data'!$H$2:$H$649,1)/COUNTIFS('Raw Data'!$B$2:$B$649,A7) -> 0.23148148 | D7: =AVERAGEIFS('Raw Data'!$G$2:$G$649,'Raw Data'!$B$2:$B$649,A7) -> 0.10488673 | E7: =IFERROR(AVERAGEIFS('Raw Data'!$G$2:$G$649,'Raw Data'!$B$2:$B$649,A7,'Raw Data'!$H$2:$H$649,1),0) -> 0.45311068 | F7: =IFERROR(AVERAGEIFS('Raw Data'!$C$2:$C$649,'Raw Data'!$B$2:$B$649,A7,'Raw Data'!$F$2:$F$649,1),0) -> 0.099985761 | G7: =IFERROR(AVERAGEIFS('Raw Data'!$D$2:$D$649,'Raw Data'!$B$2:$B$649,A7,'Raw Data'!$F$2:$F$649,1),0) -> 0.095918657 | H7: =IFERROR(AVERAGEIFS('Raw Data'!$E$2:$E$649,'Raw Data'!$B$2:$B$649,A7,'Raw Data'!$F$2:$F$649,1),0) -> 0.010113657
A8: TLT | B8: =COUNTIFS('Raw Data'!$B$2:$B$649,A8,'Raw Data'!$F$2:$F$649,1)/COUNTIFS('Raw Data'!$B$2:$B$649,A8) -> 0.5 | C8: =COUNTIFS('Raw Data'!$B$2:$B$649,A8,'Raw Data'!$H$2:$H$649,1)/COUNTIFS('Raw Data'!$B$2:$B$649,A8) -> 0.17592593 | D8: =AVERAGEIFS('Raw Data'!$G$2:$G$649,'Raw Data'!$B$2:$B$649,A8) -> 0.095108824 | E8: =IFERROR(AVERAGEIFS('Raw Data'!$G$2:$G$649,'Raw Data'!$B$2:$B$649,A8,'Raw Data'!$H$2:$H$649,1),0) -> 0.54061858 | F8: =IFERROR(AVERAGEIFS('Raw Data'!$C$2:$C$649,'Raw Data'!$B$2:$B$649,A8,'Raw Data'!$F$2:$F$649,1),0) -> 0.073974944 | G8: =IFERROR(AVERAGEIFS('Raw Data'!$D$2:$D$649,'Raw Data'!$B$2:$B$649,A8,'Raw Data'!$F$2:$F$649,1),0) -> 0.073831704 | H8: =IFERROR(AVERAGEIFS('Raw Data'!$E$2:$E$649,'Raw Data'!$B$2:$B$649,A8,'Raw Data'!$F$2:$F$649,1),0) -> 0.0081783704
A9: CASH | B9: =COUNTIFS('Raw Data'!$B$2:$B$649,A9,'Raw Data'!$F$2:$F$649,1)/COUNTIFS('Raw Data'!$B$2:$B$649,A9) -> 0 | C9: =COUNTIFS('Raw Data'!$B$2:$B$649,A9,'Raw Data'!$H$2:$H$649,1)/COUNTIFS('Raw Data'!$B$2:$B$649,A9) -> 0.064814815 | D9: =AVERAGEIFS('Raw Data'!$G$2:$G$649,'Raw Data'!$B$2:$B$649,A9) -> 0.064814815 | E9: =IFERROR(AVERAGEIFS('Raw Data'!$G$2:$G$649,'Raw Data'!$B$2:$B$649,A9,'Raw Data'!$H$2:$H$649,1),0) -> 1 | F9: =IFERROR(AVERAGEIFS('Raw Data'!$C$2:$C$649,'Raw Data'!$B$2:$B$649,A9,'Raw Data'!$F$2:$F$649,1),0) -> 0 | G9: =IFERROR(AVERAGEIFS('Raw Data'!$D$2:$D$649,'Raw Data'!$B$2:$B$649,A9,'Raw Data'!$F$2:$F$649,1),0) -> 0 | H9: =IFERROR(AVERAGEIFS('Raw Data'!$E$2:$E$649,'Raw Data'!$B$2:$B$649,A9,'Raw Data'!$F$2:$F$649,1),0) -> 0
A11: Note: CASH has no momentum signal (it is a synthetic risk-free position, not a traded ticker), so its Gate Pass Rate and momentum-signal averages are structurally 0%/blank. "Gate Pass Rate" = % of the 108 rebalance months where the blended 3M/6M/12M momentum signal was positive (i.e., eligible to be selected). "Selection Rate" = % of months the asset actually ended up with nonzero weight in the portfolio.

Sheet Raw Data
A1: Date | B1: Ticker | C1: AbsMomBlend_3_6_12M | D1: RelMom_6M | E1: Vol_20D | F1: PassedGate | G1: Weight | H1: Selected
A2: 42398 | B2: EEM | C2: -0.163802 | D2: -0.15451 | E2: 0.020002 | F2: 0 | G2: 0 | H2: =IF(G2>0,1,0) -> 0
A3: 42398 | B3: GLD | C3: -0.041077 | D3: 0.025703 | E3: 0.009086 | F3: 0 | G3: 0 | H3: =IF(G3>0,1,0) -> 0
A4: 42398 | B4: QQQ | C4: -0.039148 | D4: -0.065827 | E4: 0.018608 | F4: 0 | G4: 0 | H4: =IF(G4>0,1,0) -> 0
A5: 42398 | B5: SPY | C5: -0.05312 | D5: -0.070838 | E5: 0.014816 | F5: 0 | G5: 0 | H5: =IF(G5>0,1,0) -> 0
A6: 42398 | B6: TLT | C6: 0.018545 | D6: 0.060115 | E6: 0.007805 | F6: 1 | G6: 1 | H6: =IF(G6>0,1,0) -> 1
A7: 42398 | B7: CASH | F7: 0 | G7: 0 | H7: =IF(G7>0,1,0) -> 0
A8: 42429 | B8: EEM | C8: -0.150438 | D8: -0.100161 | E8: 0.016698 | F8: 0 | G8: 0 | H8: =IF(G8>0,1,0) -> 0
A9: 42429 | B9: GLD | C9: 0.093512 | D9: 0.101272 | E9: 0.015065 | F9: 1 | G9: 0.386528 | H9: =IF(G9>0,1,0) -> 1
A10: 42429 | B10: QQQ | C10: -0.056188 | D10: -0.024392 | E10: 0.014784 | F10: 0 | G10: 0 | H10: =IF(G10>0,1,0) -> 0
A11: 42429 | B11: SPY | C11: -0.049932 | D11: -0.017794 | E11: 0.011865 | F11: 0 | G11: 0 | H11: =IF(G11>0,1,0) -> 0
A12: 42429 | B12: TLT | C12: 0.070798 | D12: 0.087141 | E12: 0.009492 | F12: 1 | G12: 0.613472 | H12: =IF(G12>0,1,0) -> 1
A13: 42429 | B13: CASH | F13: 0 | G13: 0 | H13: =IF(G13>0,1,0) -> 0
A14: 42460 | B14: EEM | C14: 0.003068 | D14: 0.091769 | E14: 0.012104 | F14: 1 | G14: 0 | H14: =IF(G14>0,1,0) -> 0
A15: 42460 | B15: GLD | C15: 0.091851 | D15: 0.089461 | E15: 0.012126 | F15: 1 | G15: 0 | H15: =IF(G15>0,1,0) -> 0
A16: 42460 | B16: QQQ | C16: 0.035969 | D16: 0.104438 | E16: 0.006738 | F16: 1 | G16: 0.456942 | H16: =IF(G16>0,1,0) -> 1
A17: 42460 | B17: SPY | C17: 0.039183 | D17: 0.104665 | E17: 0.005669 | F17: 1 | G17: 0.543058 | H17: =IF(G17>0,1,0) -> 1
A18: 42460 | B18: TLT | C18: 0.060811 | D18: 0.066552 | E18: 0.006589 | F18: 1 | G18: 0 | H18: =IF(G18>0,1,0) -> 0
A19: 42460 | B19: CASH | F19: 0 | G19: 0 | H19: =IF(G19>0,1,0) -> 0
A20: 42489 | B20: EEM | C20: -0.020189 | D20: -0.006092 | E20: 0.012304 | F20: 0 | G20: 0 | H20: =IF(G20>0,1,0) -> 0
A21: 42489 | B21: GLD | C21: 0.12068 | D21: 0.116176 | E21: 0.010396 | F21: 1 | G21: 0.394367 | H21: =IF(G21>0,1,0) -> 1
A22: 42489 | B22: QQQ | C22: -0.018688 | D22: -0.067204 | E22: 0.008287 | F22: 0 | G22: 0 | H22: =IF(G22>0,1,0) -> 0
A23: 42489 | B23: SPY | C23: 0.026651 | D23: -0.001539 | E23: 0.006429 | F23: 1 | G23: 0 | H23: =IF(G23>0,1,0) -> 0
A24: 42489 | B24: TLT | C24: 0.044442 | D24: 0.057696 | E24: 0.00677 | F24: 1 | G24: 0.605633 | H24: =IF(G24>0,1,0) -> 1
A25: 42489 | B25: CASH | F25: 0 | G25: 0 | H25: =IF(G25>0,1,0) -> 0
A26: 42521 | B26: EEM | C26: -0.04229 | D26: -0.008953 | E26: 0.011752 | F26: 0 | G26: 0 | H26: =IF(G26>0,1,0) -> 0
A27: 42521 | B27: GLD | C27: 0.049941 | D27: 0.146272 | E27: 0.008208 | F27: 1 | G27: 0.435812 | H27: =IF(G27>0,1,0) -> 1
A28: 42521 | B28: QQQ | C28: 0.009086 | D28: -0.02891 | E28: 0.008515 | F28: 1 | G28: 0 | H28: =IF(G28>0,1,0) -> 0
A29: 42521 | B29: SPY | C29: 0.030051 | D29: 0.01249 | E29: 0.006918 | F29: 1 | G29: 0 | H29: =IF(G29>0,1,0) -> 0
A30: 42521 | B30: TLT | C30: 0.068696 | D30: 0.08905 | E30: 0.00634 | F30: 1 | G30: 0.564188 | H30: =IF(G30>0,1,0) -> 1
A31: 42521 | B31: CASH | F31: 0 | G31: 0 | H31: =IF(G31>0,1,0) -> 0
A32: 42551 | B32: EEM | C32: -0.008377 | D32: 0.072467 | E32: 0.020432 | F32: 0 | G32: 0 | H32: =IF(G32>0,1,0) -> 0
A33: 42551 | B33: GLD | C33: 0.152659 | D33: 0.246993 | E33: 0.014591 | F33: 1 | G33: 0.411847 | H33: =IF(G33>0,1,0) -> 1
A34: 42551 | B34: QQQ | C34: -0.020196 | D34: -0.045235 | E34: 0.013861 | F34: 0 | G34: 0 | H34: =IF(G34>0,1,0) -> 0
A35: 42551 | B35: SPY | C35: 0.025624 | D35: 0.027803 | E35: 0.012271 | F35: 1 | G35: 0 | H35: =IF(G35>0,1,0) -> 0
A36: 42551 | B36: TLT | C36: 0.154955 | D36: 0.168655 | E36: 0.010217 | F36: 1 | G36: 0.588153 | H36: =IF(G36>0,1,0) -> 1
A37: 42551 | B37: CASH | F37: 0 | G37: 0 | H37: =IF(G37>0,1,0) -> 0
A38: 42580 | B38: EEM | C38: 0.088115 | D38: 0.193801 | E38: 0.009914 | F38: 1 | G38: 0.49725 | H38: =IF(G38>0,1,0) -> 1
A39: 42580 | B39: GLD | C39: 0.162024 | D39: 0.205984 | E39: 0.009805 | F39: 1 | G39: 0.50275 | H39: =IF(G39>0,1,0) -> 1
A40: 42580 | B40: QQQ | C40: 0.081758 | D40: 0.112836 | E40: 0.005292 | F40: 1 | G40: 0 | H40: =IF(G40>0,1,0) -> 0
...

Sheet Momentum Signals (Wide)
A1: Date | B1: absmom_EEM | C1: absmom_GLD | D1: absmom_QQQ | E1: absmom_SPY | F1: absmom_TLT | G1: relmom_EEM | H1: relmom_GLD | I1: relmom_QQQ | J1: relmom_SPY | K1: relmom_TLT
A2: 42398 | B2: -0.163802 | C2: -0.041077 | D2: -0.039148 | E2: -0.05312 | F2: 0.018545 | G2: -0.15451 | H2: 0.025703 | I2: -0.065827 | J2: -0.070838 | K2: 0.060115
A3: 42429 | B3: -0.150438 | C3: 0.093512 | D3: -0.056188 | E3: -0.049932 | F3: 0.070798 | G3: -0.100161 | H3: 0.101272 | I3: -0.024392 | J3: -0.017794 | K3: 0.087141
A4: 42460 | B4: 0.003068 | C4: 0.091851 | D4: 0.035969 | E4: 0.039183 | F4: 0.060811 | G4: 0.091769 | H4: 0.089461 | I4: 0.104438 | J4: 0.104665 | K4: 0.066552
A5: 42489 | B5: -0.020189 | C5: 0.12068 | D5: -0.018688 | E5: 0.026651 | F5: 0.044442 | G5: -0.006092 | H5: 0.116176 | I5: -0.067204 | J5: -0.001539 | K5: 0.057696
A6: 42521 | B6: -0.04229 | C6: 0.049941 | D6: 0.009086 | E6: 0.030051 | F6: 0.068696 | G6: -0.008953 | H6: 0.146272 | I6: -0.02891 | J6: 0.01249 | K6: 0.08905
A7: 42551 | B7: -0.008377 | C7: 0.152659 | D7: -0.020196 | E7: 0.025624 | F7: 0.154955 | G7: 0.072467 | H7: 0.246993 | I7: -0.045235 | J7: 0.027803 | K7: 0.168655
A8: 42580 | B8: 0.088115 | C8: 0.162024 | D8: 0.081758 | E8: 0.080804 | F8: 0.139536 | G8: 0.193801 | H8: 0.205984 | I8: 0.112836 | J8: 0.132432 | K8: 0.125175
A9: 42613 | B9: 0.132272 | C9: 0.084993 | D9: 0.109838 | E9: 0.097852 | F9: 0.110579 | G9: 0.144096 | H9: 0.033546 | I9: 0.108553 | J9: 0.099397 | K9: 0.0913
A10: 42643 | B10: 0.120413 | C10: 0.079103 | D10: 0.120372 | E10: 0.081715 | F10: 0.059544 | G10: 0.118679 | H10: 0.081705 | I10: 0.085451 | J10: 0.059506 | K10: 0.061706
A11: 42674 | B11: 0.082793 | C11: 0.014469 | D11: 0.058776 | E11: 0.025628 | F11: 0.023442 | G11: 0.123067 | H11: -0.008295 | I11: 0.112224 | J11: 0.041592 | K11: 0.023568
A12: 42704 | B12: 0.034971 | C12: -0.015241 | D12: 0.037165 | E12: 0.047709 | F12: -0.070634 | G12: 0.072189 | H12: -0.033889 | I12: 0.068079 | J12: 0.05564 | K12: -0.076208
A13: 42734 | B13: 0.024994 | C13: -0.064555 | D13: 0.058044 | E13: 0.078672 | F13: -0.085665 | G13: 0.020764 | H13: -0.146406 | I13: 0.102222 | J13: 0.076521 | K13: -0.142305
... A109: 45656 | B109: -0.000722 | C109: 0.121001 | D109: 0.130776 | E109: 0.121343 | F109: -0.059859 | G109: -0.000506 | H109: 0.11625 | I109: 0.073139 | J109: 0.08558 | K109: -0.003225

Sheet Weights (Wide)
A1: Date | B1: CASH | C1: EEM | D1: GLD | E1: QQQ | F1: SPY | G1: TLT
A2: 42398 | B2: 0 | C2: 0 | D2: 0 | E2: 0 | F2: 0 | G2: 1
A3: 42429 | B3: 0 | C3: 0 | D3: 0.386528 | E3: 0 | F3: 0 | G3: 0.613472
A4: 42460 | B4: 0 | C4: 0 | D4: 0 | E4: 0.456942 | F4: 0.543058 | G4: 0
A5: 42489 | B5: 0 | C5: 0 | D5: 0.394367 | E5: 0 | F5: 0 | G5: 0.605633
A6: 42521 | B6: 0 | C6: 0 | D6: 0.435812 | E6: 0 | F6: 0 | G6: 0.564188
A7: 42551 | B7: 0 | C7: 0 | D7: 0.411847 | E7: 0 | F7: 0 | G7: 0.588153
A8: 42580 | B8: 0 | C8: 0.49725 | D8: 0.50275 | E8: 0 | F8: 0 | G8: 0
A9: 42613 | B9: 0 | C9: 0.312177 | D9: 0 | E9: 0.687823 | F9: 0 | G9: 0
A10: 42643 | B10: 0 | C10: 0.384769 | D10: 0 | E10: 0.615231 | F10: 0 | G10: 0
A11: 42674 | B11: 0 | C11: 0.379625 | D11: 0 | E11: 0.620375 | F11: 0 | G11: 0
A12: 42704 | B12: 0 | C12: 0.376803 | D12: 0 | E12: 0.623197 | F12: 0 | G12: 0
A13: 42734 | B13: 0 | C13: 0 | D13: 0 | E13: 0.456706 | F13: 0.543294 | G13: 0
... A109: 45656 | B109: 0 | C109: 0 | D109: 0.511421 | E109: 0 | F109: 0.488579 | G109: 0
